If submitted, this report will be used by core maintainers to improve
future releases of conda.
Would you like conda to send this report to the core maintainers? [y/N]: 
Error while loading conda entry point: conda-build ((-2147024894, '系统找不到指定的文件。', None, None))
KeyError('pkgs_dirs')
Traceback (most recent call last):
  File "D:\LearnApps\Python\Anaconda\Lib\site-packages\conda\exception_handler.py", line 17, in __call__
    return func(*args, **kwargs)
           ^^^^^^^^^^^^^^^^^^^^^
  File "D:\LearnApps\Python\Anaconda\Lib\site-packages\conda\cli\main.py", line 57, in main_subshell
    context.__init__(argparse_args=args)
  File "D:\LearnApps\Python\Anaconda\Lib\site-packages\conda\base\context.py", line 459, in __init__
    CONDA_PREFIX=determine_target_prefix(self, argparse_args),
                 ^^^^^^^^^^^^^^^^^^^^^^^^^^^^^^^^^^^^^^^^^^^^
  File "D:\LearnApps\Python\Anaconda\Lib\site-packages\conda\base\context.py", line 1975, in determine_target_prefix
    return validate_prefix_name(prefix_name, ctx=ctx)
           ^^^^^^^^^^^^^^^^^^^^^^^^^^^^^^^^^^^^^^^^^^
  File "D:\LearnApps\Python\Anaconda\Lib\site-packages\conda\base\context.py", line 1935, in validate_prefix_name
    return locate_prefix_by_name(prefix_name)
           ^^^^^^^^^^^^^^^^^^^^^^^^^^^^^^^^^^
  File "D:\LearnApps\Python\Anaconda\Lib\site-packages\conda\base\context.py", line 1894, in locate_prefix_by_name
    envs_dirs = context.envs_dirs
                ^^^^^^^^^^^^^^^^^
  File "D:\LearnApps\Python\Anaconda\Lib\site-packages\conda\base\context.py", line 657, in envs_dirs
    return mockable_context_envs_dirs(
           ^^^^^^^^^^^^^^^^^^^^^^^^^^^
  File "D:\LearnApps\Python\Anaconda\Lib\site-packages\conda\base\context.py", line 125, in mockable_context_envs_dirs
    fixed_dirs.append(join(user_data_dir(APP_NAME, APP_NAME), "envs"))
                           ^^^^^^^^^^^^^^^^^^^^^^^^^^^^^^^^^
  File "D:\LearnApps\Python\Anaconda\Lib\site-packages\conda\_vendor\appdirs.py", line 67, in user_data_dir
    path = os.path.join(_get_win_folder(const), appauthor, appname)
                        ^^^^^^^^^^^^^^^^^^^^^^
  File "D:\LearnApps\Python\Anaconda\Lib\site-packages\conda\_vendor\appdirs.py", line 266, in _get_win_folder_with_pywin32
    dir = shell.SHGetFolderPath(0, getattr(shellcon, csidl_name), 0, 0)
          ^^^^^^^^^^^^^^^^^^^^^^^^^^^^^^^^^^^^^^^^^^^^^^^^^^^^^^^^^^^^^
pywintypes.com_error: (-2147024894, '系统找不到指定的文件。', None, None)

During handling of the above exception, another exception occurred:

Traceback (most recent call last):
  File "D:\LearnApps\Python\Anaconda\Lib\site-packages\conda\exception_handler.py", line 166, in print_unexpected_error_report
    get_main_info_str(error_report["conda_info"])
  File "D:\LearnApps\Python\Anaconda\Lib\site-packages\conda\cli\main_info.py", line 254, in get_main_info_str
    info_dict[f"_{key}"] = ("\n" + 26 * " ").join(map(str, info_dict[key]))
                                                           ~~~~~~~~~^^^^^
KeyError: 'pkgs_dirs'

# >>>>>>>>>>>>>>>>>>>>>> ERROR REPORT <<<<<<<<<<<<<<<<<<<<<<

    Traceback (most recent call last):
      File "D:\LearnApps\Python\Anaconda\Lib\site-packages\conda\exception_handler.py", line 17, in __call__
        return func(*args, **kwargs)
               ^^^^^^^^^^^^^^^^^^^^^
      File "D:\LearnApps\Python\Anaconda\Lib\site-packages\conda\cli\main.py", line 57, in main_subshell
        context.__init__(argparse_args=args)
      File "D:\LearnApps\Python\Anaconda\Lib\site-packages\conda\base\context.py", line 459, in __init__
        CONDA_PREFIX=determine_target_prefix(self, argparse_args),
                     ^^^^^^^^^^^^^^^^^^^^^^^^^^^^^^^^^^^^^^^^^^^^
      File "D:\LearnApps\Python\Anaconda\Lib\site-packages\conda\base\context.py", line 1975, in determine_target_prefix
        return validate_prefix_name(prefix_name, ctx=ctx)
               ^^^^^^^^^^^^^^^^^^^^^^^^^^^^^^^^^^^^^^^^^^
      File "D:\LearnApps\Python\Anaconda\Lib\site-packages\conda\base\context.py", line 1935, in validate_prefix_name
        return locate_prefix_by_name(prefix_name)
               ^^^^^^^^^^^^^^^^^^^^^^^^^^^^^^^^^^
      File "D:\LearnApps\Python\Anaconda\Lib\site-packages\conda\base\context.py", line 1894, in locate_prefix_by_name
        envs_dirs = context.envs_dirs
                    ^^^^^^^^^^^^^^^^^
      File "D:\LearnApps\Python\Anaconda\Lib\site-packages\conda\base\context.py", line 657, in envs_dirs
        return mockable_context_envs_dirs(
               ^^^^^^^^^^^^^^^^^^^^^^^^^^^
      File "D:\LearnApps\Python\Anaconda\Lib\site-packages\conda\base\context.py", line 125, in mockable_context_envs_dirs
        fixed_dirs.append(join(user_data_dir(APP_NAME, APP_NAME), "envs"))
                               ^^^^^^^^^^^^^^^^^^^^^^^^^^^^^^^^^
      File "D:\LearnApps\Python\Anaconda\Lib\site-packages\conda\_vendor\appdirs.py", line 67, in user_data_dir
        path = os.path.join(_get_win_folder(const), appauthor, appname)
                            ^^^^^^^^^^^^^^^^^^^^^^
      File "D:\LearnApps\Python\Anaconda\Lib\site-packages\conda\_vendor\appdirs.py", line 266, in _get_win_folder_with_pywin32
        dir = shell.SHGetFolderPath(0, getattr(shellcon, csidl_name), 0, 0)
              ^^^^^^^^^^^^^^^^^^^^^^^^^^^^^^^^^^^^^^^^^^^^^^^^^^^^^^^^^^^^^
    pywintypes.com_error: (-2147024894, '系统找不到指定的文件。', None, None)

`$ D:\LearnApps\Python\Anaconda\Scripts\conda-script.py list -n new1`

  environment variables:
conda info could not be constructed.
KeyError('pkgs_dirs')

An unexpected error has occurred. Conda has prepared the above report.
If you suspect this error is being caused by a malfunctioning plugin,
consider using the --no-plugins option to turn off plugins.

Example: conda --no-plugins install <package>

Alternatively, you can set the CONDA_NO_PLUGINS environment variable on
the command line to run the command without plugins enabled.

Example: CONDA_NO_PLUGINS=true conda install <package>

